Traceback (most recent call last):
  File "/opt/hostedtoolcache/Python/3.8.17/x64/lib/python3.8/site-packages/jupyter_cache/executors/utils.py", line 58, in single_nb_execution
    executenb(
  File "/opt/hostedtoolcache/Python/3.8.17/x64/lib/python3.8/site-packages/nbclient/client.py", line 1305, in execute
    return NotebookClient(nb=nb, resources=resources, km=km, **kwargs).execute()
  File "/opt/hostedtoolcache/Python/3.8.17/x64/lib/python3.8/site-packages/jupyter_core/utils/__init__.py", line 166, in wrapped
    return loop.run_until_complete(inner)
  File "/opt/hostedtoolcache/Python/3.8.17/x64/lib/python3.8/asyncio/base_events.py", line 616, in run_until_complete
    return future.result()
  File "/opt/hostedtoolcache/Python/3.8.17/x64/lib/python3.8/site-packages/nbclient/client.py", line 705, in async_execute
    await self.async_execute_cell(
  File "/opt/hostedtoolcache/Python/3.8.17/x64/lib/python3.8/site-packages/nbclient/client.py", line 1058, in async_execute_cell
    await self._check_raise_for_error(cell, cell_index, exec_reply)
  File "/opt/hostedtoolcache/Python/3.8.17/x64/lib/python3.8/site-packages/nbclient/client.py", line 914, in _check_raise_for_error
    raise CellExecutionError.from_cell_and_msg(cell, exec_reply_content)
nbclient.exceptions.CellExecutionError: An error occurred while executing the following cell:
------------------
import matplotlib.pyplot as plt
from echemsuite.cyclicvoltammetry import CyclicVoltammetry

# Load the data to plot in a CyclicVoltammetry object
cv = CyclicVoltammetry("../utils/cv_sample.DTA")

# Setup a figure and set a global font size
plt.rcParams.update({'font.size': 18}) 
fig = plt.figure(figsize= (6, 6))

# Plot all the cycles contained in the cyclic-voltammetry experiment
for index, (current, voltage) in enumerate(cv):
    plt.plot(voltage, [1e6*i for i in current], label=f"{index}")

# Set the axis labels
plt.xlabel(r"V vs $\mathrm{V}_\mathrm{ref}$ [$V$]", size=20)
plt.ylabel(r"I [$\mu A$]", size=20)

# Add a legend to the plot
plt.legend(title="Cycle")

# Setup a grid
plt.grid(which="major", c="#DDDDDD")
plt.grid(which="minor", c="#EEEEEE")

# Render the plot
plt.tight_layout()
plt.show()
------------------


[0;31m---------------------------------------------------------------------------[0m
[0;31mImportError[0m                               Traceback (most recent call last)
Cell [0;32mIn[1], line 2[0m
[1;32m      1[0m [38;5;28;01mimport[39;00m [38;5;21;01mmatplotlib[39;00m[38;5;21;01m.[39;00m[38;5;21;01mpyplot[39;00m [38;5;28;01mas[39;00m [38;5;21;01mplt[39;00m
[0;32m----> 2[0m [38;5;28;01mfrom[39;00m [38;5;21;01mechemsuite[39;00m[38;5;21;01m.[39;00m[38;5;21;01mcyclicvoltammetry[39;00m [38;5;28;01mimport[39;00m CyclicVoltammetry
[1;32m      4[0m [38;5;66;03m# Load the data to plot in a CyclicVoltammetry object[39;00m
[1;32m      5[0m cv [38;5;241m=[39m CyclicVoltammetry([38;5;124m"[39m[38;5;124m../utils/cv_sample.DTA[39m[38;5;124m"[39m)

[0;31mImportError[0m: cannot import name 'CyclicVoltammetry' from 'echemsuite.cyclicvoltammetry' (unknown location)

